<?xml version="1.0" ?>
<!-- =================================================================================== -->
<!-- |    This document was autogenerated by xacro from /home/u20/catkin_ws/src/mycobot_sim_3.0/mycobot_description/urdf/mycobot_320_pi_2022/new_mycobot_pro_320_pi_moveit_2022.urdf.xacro | -->
<!-- |    EDITING THIS FILE BY HAND IS NOT RECOMMENDED                                 | -->
<!-- =================================================================================== -->
<robot name="firefighter">
    <!-- <xacro:macro name="cylinder_inertia" params="m r h">
        <inertia    ixx="${m*(3*r*r+h*h)/12}" ixy = "0" ixz = "0"
                    iyy="${m*(3*r*r+h*h)/12}" iyz = "0"
                    izz="${m*r*r/2}" />
  </xacro:macro>

  <xacro:macro name="box_inertia" params="m x y z">
          <inertia  ixx="${m*(y*y+z*z)/12}" ixy = "0" ixz = "0"
                    iyy="${m*(x*x+z*z)/12}" iyz = "0"
                    izz="${m*(x*x+z*z)/12}" />
  </xacro:macro>

  <xacro:macro name="sphere_inertia" params="m r">
          <inertia  ixx="${2*m*r*r/5}" ixy = "0" ixz = "0"
                    iyy="${2*m*r*r/5}" iyz = "0"
                    izz="${2*m*r*r/5}" />
  </xacro:macro>-->
    <!-- INTEL REALSENSE D435 -->
    <material name="black">
        <color rgba="0.0 0.0 0.0 1.0" />
    </material>
    <material name="blue">
        <color rgba="0.0 0.0 0.8 1.0" />
    </material>
    <material name="green">
        <color rgba="0.0 0.8 0.0 1.0" />
    </material>
    <material name="grey">
        <color rgba="0.2 0.2 0.2 1.0" />
    </material>
    <material name="silver">
        <color rgba="0.9137254901960784 0.9137254901960784 0.8470588235294118 1.0" />
    </material>
    <material name="orange">
        <color rgba="1.0 0.4235294117647059 0.0392156862745098 1.0" />
    </material>
    <material name="brown">
        <color rgba="0.8705882352941177 0.8117647058823529 0.7647058823529411 1.0" />
    </material>
    <material name="red">
        <color rgba="0.8 0.0 0.0 1.0" />
    </material>
    <material name="white">
        <color rgba="1.0 1.0 1.0 1.0" />
    </material>
    <!-- ros_control plugin -->
    <gazebo>
        <plugin filename="libgazebo_ros_control.so" name="gazebo_ros_control">
            <robotNamespace>/go1_gazebo</robotNamespace>
            <robotSimType>gazebo_ros_control/DefaultRobotHWSim</robotSimType>
        </plugin>
    </gazebo>
    <!-- Show the trajectory of trunk center. -->
    <gazebo>
        <plugin filename="libLinkPlot3DPlugin.so" name="3dplot">
            <frequency>10</frequency>
            <plot>
                <link>base_link</link>
                <pose>0 0 0 0 0 0</pose>
                <material>Gazebo/Yellow</material>
            </plot>
        </plugin>
    </gazebo>
    <!-- Show the trajectory of foot. You can add another trajectory about another foot. -->
    <!-- <gazebo>
        <plugin name="3dplot" filename="libLinkPlot3DPlugin.so">
            <frequency>100</frequency>
            <plot>
                <link>FL_foot</link>
                <pose>0 0 0 0 0 0</pose>
                <material>Gazebo/Green</material>
            </plot>
        </plugin>
    </gazebo> -->
    <gazebo>
        <plugin filename="libgazebo_ros_force.so" name="gazebo_ros_force">
            <bodyName>trunk</bodyName>
            <topicName>/apply_force/trunk</topicName>
        </plugin>
    </gazebo>
    <gazebo reference="imu_link">
        <gravity>true</gravity>
        <sensor name="imu_sensor" type="imu">
            <always_on>true</always_on>
            <update_rate>1000</update_rate>
            <visualize>true</visualize>
            <topic>__default_topic__</topic>
            <plugin filename="libgazebo_ros_imu_sensor.so" name="imu_plugin">
                <topicName>trunk_imu</topicName>
                <bodyName>imu_link</bodyName>
                <updateRateHZ>1000.0</updateRateHZ>
                <gaussianNoise>0.0</gaussianNoise>
                <xyzOffset>0 0 0</xyzOffset>
                <rpyOffset>0 0 0</rpyOffset>
                <frameName>imu_link</frameName>
            </plugin>
            <pose>0 0 0 0 0 0</pose>
        </sensor>
    </gazebo>
    <!-- Depth camera -->
    <!-- <gazebo>
        <plugin name="camera_plugin" filename="libgazebo_ros_openni_kinect.so">
            <baseline>0.025</baseline>
            <always_on>true</always_on>
            <updateRate>0.0</updateRate>
            <cameraName>unitree_camera_left</cameraName>
            <frameName>depthCamera_link_left</frameName>
            <imageTopicName>rgb/imageRaw_left</imageTopicName>
            <depthImageTopicName>depth/imageRaw_left</depthImageTopicName>
            <pointCloudTopicName>depth/points_left</pointCloudTopicName>
            <cameraInfoTopicName>rgb/cameraInfo_left</cameraInfoTopicName>              
            <depthImageCameraInfoTopicName>depth/cameraInfo_left</depthImageCameraInfoTopicName>            
            <pointCloudCutoff>0.1</pointCloudCutoff>                
            <pointCloudCutoffMax>1.5</pointCloudCutoffMax>                
            <distortionK1>0.0</distortionK1>
            <distortionK2>0.0</distortionK2>
            <distortionK3>0.0</distortionK3>
            <distortionT1>0.0</distortionT1>
            <distortionT2>0.0</distortionT2>
            <CxPrime>0.0</CxPrime>
            <Cx>0.0045</Cx>
            <Cy>0.0039</Cy>
            <focalLength>0.004</focalLength>
            <hackBaseline>0.0</hackBaseline>
        </plugin>
    </gazebo> -->
    <!-- <gazebo reference="depthCamera_link_left">
        <sensor name="unitree_camera_left" type="depth_camera">
            <update_rate>16</update_rate>
            <always_on>true</always_on>
            <visualize>true</visualize>
            <camera>
                <horizontal_fov>2.094</horizontal_fov>
                <image>
                    <width>928</width>
                    <height>800</height>
                    <format>R8G8B8</format>
                </image>
                <depth_camera></depth_camera>
                <clip>
                    <near>0.1</near>
                    <far>100</far>
                </clip>
            </camera>
            <plugin name="camera_plugin" filename="libgazebo_ros_openni_kinect.so">
                <baseline>0.025</baseline>
                <always_on>true</always_on>
                <updateRate>0.0</updateRate>
                <cameraName>unitree_camera_left</cameraName>
                <frameName>depthCamera_link_left</frameName>
                <imageTopicName>rgb/imageRaw_left</imageTopicName>
                <depthImageTopicName>depth/imageRaw_left</depthImageTopicName>
                <pointCloudTopicName>depth/points_left</pointCloudTopicName>
                <cameraInfoTopicName>rgb/cameraInfo_left</cameraInfoTopicName>              
                <depthImageCameraInfoTopicName>depth/cameraInfo_left</depthImageCameraInfoTopicName>            
                <pointCloudCutoff>0.1</pointCloudCutoff>                
                <pointCloudCutoffMax>1.5</pointCloudCutoffMax>                
                <distortionK1>0.0</distortionK1>
                <distortionK2>0.0</distortionK2>
                <distortionK3>0.0</distortionK3>
                <distortionT1>0.0</distortionT1>
                <distortionT2>0.0</distortionT2>
                <CxPrime>0.0</CxPrime>
                <Cx>0.0045</Cx>
                <Cy>0.0039</Cy>
                <focalLength>0.004</focalLength>
                <hackBaseline>0.0</hackBaseline>
            </plugin>
        </sensor>
    </gazebo> -->
    <gazebo reference="depthCamera_link_left">
        <sensor name="camera_link_camera" type="depth">
            <update_rate>20</update_rate>
            <camera>
                <horizontal_fov>1.047198</horizontal_fov>
                <image>
                    <width>640</width>
                    <height>480</height>
                    <format>R8G8B8</format>
                </image>
                <clip>
                    <near>0.05</near>
                    <far>3</far>
                </clip>
            </camera>
            <plugin filename="libgazebo_ros_openni_kinect.so" name="camera_link_controller">
                <baseline>0.2</baseline>
                <alwaysOn>true</alwaysOn>
                <updateRate>1.0</updateRate>
                <cameraName>camera_link_ir</cameraName>
                <imageTopicName>/camera_link/color/image_raw</imageTopicName>
                <cameraInfoTopicName>/camera_link/color/camera_info</cameraInfoTopicName>
                <depthImageTopicName>/camera_link/depth/image_raw</depthImageTopicName>
                <depthImageInfoTopicName>/camera_link/depth/camera_info</depthImageInfoTopicName>
                <pointCloudTopicName>/camera_link/depth/points</pointCloudTopicName>
                <frameName>depthCamera_link_left</frameName>
                <pointCloudCutoff>0.5</pointCloudCutoff>
                <pointCloudCutoffMax>3.0</pointCloudCutoffMax>
                <distortionK1>0.00000001</distortionK1>
                <distortionK2>0.00000001</distortionK2>
                <distortionK3>0.00000001</distortionK3>
                <distortionT1>0.00000001</distortionT1>
                <distortionT2>0.00000001</distortionT2>
                <CxPrime>0</CxPrime>
                <Cx>0</Cx>
                <Cy>0</Cy>
                <focalLength>0</focalLength>
                <hackBaseline>0</hackBaseline>
            </plugin>
        </sensor>
    </gazebo>
    <gazebo reference="laser">
        <material>Gazebo/FlatRed</material>
        <sensor name="lds_lfcd_sensor" type="ray">
            <pose>0 0 0 0 0 0</pose>
            <visualize>false</visualize>
            <update_rate>5</update_rate>
            <ray>
                <scan>
                    <horizontal>
                        <samples>360</samples>
                        <resolution>1</resolution>
                        <min_angle>0.0</min_angle>
                        <max_angle>6.28319</max_angle>
                    </horizontal>
                </scan>
                <range>
                    <min>0.120</min>
                    <max>3.5</max>
                    <resolution>0.015</resolution>
                </range>
                <noise>
                    <type>gaussian</type>
                    <mean>0.0</mean>
                    <stddev>0.01</stddev>
                </noise>
            </ray>
            <plugin filename="libgazebo_ros_laser.so" name="gazebo_ros_lds_lfcd_controller">
                <topicName>ori_scan</topicName>
                <frameName>laser</frameName>
            </plugin>
        </sensor>
    </gazebo>
    <!-- Foot contacts. -->
    <gazebo reference="FR_calf">
        <sensor name="FR_foot_contact" type="contact">
            <update_rate>100</update_rate>
            <plugin filename="libunitreeFootContactPlugin.so" name="contactPlugin" />
            <contact>
                <collision>FR_calf_fixed_joint_lump__FR_foot_collision_1</collision>
            </contact>
        </sensor>
    </gazebo>
    <gazebo reference="FL_calf">
        <sensor name="FL_foot_contact" type="contact">
            <update_rate>100</update_rate>
            <plugin filename="libunitreeFootContactPlugin.so" name="contactPlugin" />
            <contact>
                <collision>FL_calf_fixed_joint_lump__FL_foot_collision_1</collision>
            </contact>
        </sensor>
    </gazebo>
    <gazebo reference="RR_calf">
        <sensor name="RR_foot_contact" type="contact">
            <update_rate>100</update_rate>
            <plugin filename="libunitreeFootContactPlugin.so" name="contactPlugin" />
            <contact>
                <collision>RR_calf_fixed_joint_lump__RR_foot_collision_1</collision>
            </contact>
        </sensor>
    </gazebo>
    <gazebo reference="RL_calf">
        <sensor name="RL_foot_contact" type="contact">
            <update_rate>100</update_rate>
            <plugin filename="libunitreeFootContactPlugin.so" name="contactPlugin" />
            <contact>
                <collision>RL_calf_fixed_joint_lump__RL_foot_collision_1</collision>
            </contact>
        </sensor>
    </gazebo>
    <!-- Visualization of Foot contacts. -->
    <gazebo reference="FR_foot">
        <visual>
            <plugin filename="libunitreeDrawForcePlugin.so" name="drawForcePlugin">
                <topicName>FR_foot_contact</topicName>
            </plugin>
        </visual>
    </gazebo>
    <gazebo reference="FL_foot">
        <visual>
            <plugin filename="libunitreeDrawForcePlugin.so" name="drawForcePlugin">
                <topicName>FL_foot_contact</topicName>
            </plugin>
        </visual>
    </gazebo>
    <gazebo reference="RR_foot">
        <visual>
            <plugin filename="libunitreeDrawForcePlugin.so" name="drawForcePlugin">
                <topicName>RR_foot_contact</topicName>
            </plugin>
        </visual>
    </gazebo>
    <gazebo reference="RL_foot">
        <visual>
            <plugin filename="libunitreeDrawForcePlugin.so" name="drawForcePlugin">
                <topicName>RL_foot_contact</topicName>
            </plugin>
        </visual>
    </gazebo>
    <gazebo reference="base_link">
        <material>Gazebo/Green</material>
        <turnGravityOff>false</turnGravityOff>
    </gazebo>
    <gazebo reference="trunk">
        <mu1>0.2</mu1>
        <mu2>0.2</mu2>
        <kp value="1000000.0" />
        <kd value="1.0" />
    </gazebo>
    <gazebo reference="stick_link">
        <mu1>0.2</mu1>
        <mu2>0.2</mu2>
        <material>Gazebo/White</material>
    </gazebo>
    <gazebo reference="imu_link">
        <mu1>0.2</mu1>
        <mu2>0.2</mu2>
        <material>Gazebo/Red</material>
    </gazebo>
    <!-- FL leg -->
    <gazebo reference="FL_hip">
        <mu1>0.2</mu1>
        <mu2>0.2</mu2>
        <material>Gazebo/DarkGrey</material>
    </gazebo>
    <gazebo reference="FL_thigh">
        <mu1>0.2</mu1>
        <mu2>0.2</mu2>
        <self_collide>1</self_collide>
        <material>Gazebo/DarkGrey</material>
        <kp value="1000000.0" />
        <kd value="1.0" />
    </gazebo>
    <gazebo reference="FL_calf">
        <mu1>0.2</mu1>
        <mu2>0.2</mu2>
        <self_collide>1</self_collide>
    </gazebo>
    <gazebo reference="FL_foot">
        <mu1>0.6</mu1>
        <mu2>0.6</mu2>
        <self_collide>1</self_collide>
        <material>Gazebo/DarkGrey</material>
        <kp value="1000000.0" />
        <kd value="1.0" />
    </gazebo>
    <!-- FR leg -->
    <gazebo reference="FR_hip">
        <mu1>0.2</mu1>
        <mu2>0.2</mu2>
        <material>Gazebo/DarkGrey</material>
    </gazebo>
    <gazebo reference="FR_thigh">
        <mu1>0.2</mu1>
        <mu2>0.2</mu2>
        <self_collide>1</self_collide>
        <material>Gazebo/DarkGrey</material>
        <kp value="1000000.0" />
        <kd value="1.0" />
    </gazebo>
    <gazebo reference="FR_calf">
        <mu1>0.2</mu1>
        <mu2>0.2</mu2>
        <self_collide>1</self_collide>
    </gazebo>
    <gazebo reference="FR_foot">
        <mu1>0.6</mu1>
        <mu2>0.6</mu2>
        <self_collide>1</self_collide>
        <material>Gazebo/DarkGrey</material>
        <kp value="1000000.0" />
        <kd value="1.0" />
    </gazebo>
    <!-- RL leg -->
    <gazebo reference="RL_hip">
        <mu1>0.2</mu1>
        <mu2>0.2</mu2>
        <material>Gazebo/DarkGrey</material>
    </gazebo>
    <gazebo reference="RL_thigh">
        <mu1>0.2</mu1>
        <mu2>0.2</mu2>
        <self_collide>1</self_collide>
        <material>Gazebo/DarkGrey</material>
        <kp value="1000000.0" />
        <kd value="1.0" />
    </gazebo>
    <gazebo reference="RL_calf">
        <mu1>0.2</mu1>
        <mu2>0.2</mu2>
        <self_collide>1</self_collide>
    </gazebo>
    <gazebo reference="RL_foot">
        <mu1>0.6</mu1>
        <mu2>0.6</mu2>
        <self_collide>1</self_collide>
        <material>Gazebo/DarkGrey</material>
        <kp value="1000000.0" />
        <kd value="1.0" />
    </gazebo>
    <!-- RR leg -->
    <gazebo reference="RR_hip">
        <mu1>0.2</mu1>
        <mu2>0.2</mu2>
        <material>Gazebo/DarkGrey</material>
    </gazebo>
    <gazebo reference="RR_thigh">
        <mu1>0.2</mu1>
        <mu2>0.2</mu2>
        <self_collide>1</self_collide>
        <material>Gazebo/DarkGrey</material>
        <kp value="1000000.0" />
        <kd value="1.0" />
    </gazebo>
    <gazebo reference="RR_calf">
        <mu1>0.2</mu1>
        <mu2>0.2</mu2>
        <self_collide>1</self_collide>
    </gazebo>
    <gazebo reference="RR_foot">
        <mu1>0.6</mu1>
        <mu2>0.6</mu2>
        <self_collide>1</self_collide>
        <material>Gazebo/DarkGrey</material>
        <kp value="1000000.0" />
        <kd value="1.0" />
    </gazebo>
    <!-- <xacro:include filename="$(find go1_gazebo)/launch/stairs.urdf.xacro"/> -->
    <!-- <xacro:stairs stairs="15" xpos="0" ypos="0" zpos="0" /> -->
    <!-- Rotor related joint and link is only for demonstrate location. -->
    <!-- Actually, the rotor will rotate and the joint is not fixed. Reduction ratio should be considered. -->
    <link name="base_link">
        <visual>
            <origin rpy="0 0 0" xyz="0 0 0" />
            <geometry>
                <box size="0.001 0.001 0.001" />
            </geometry>
        </visual>
    </link>
    <joint name="floating_base" type="fixed">
        <origin rpy="0 0 0" xyz="0 0 0" />
        <parent link="base_link" />
        <child link="trunk" />
    </joint>
    <link name="laser">
        <visual>
            <origin rpy="0 0 0" xyz="0 0 0" />
            <geometry>
                <box size="0.01 0.01 0.01" />
            </geometry>
        </visual>
    </link>
    <joint name="laser_joint" type="fixed">
        <origin rpy="0 0 0" xyz="0.3 0 -0.08" />
        <!--pos-->
        <parent link="base_link" />
        <child link="laser" />
    </joint>
    <link name="trunk">
        <visual>
            <origin rpy="0 0 0" xyz="0 0 0" />
            <geometry>
                <mesh filename="package://go2_description/meshes/trunk.dae" scale="1 1 1" />
            </geometry>
            <!-- <material name="orange"/> -->
        </visual>
        <collision>
            <origin rpy="0 0 0" xyz="0 0 0" />
            <geometry>
                <box size="0.3762 0.0935 0.114" />
            </geometry>
        </collision>
        <inertial>
            <origin rpy="0 0 0" xyz="0.021112 0.0 -0.005366" />
            <mass value="6.921" />
            <inertia ixx="0.02448" ixy="0.00012166" ixz="0.0014849" iyy="0.098077" iyz="-3.12e-05" izz="0.107" />
        </inertial>
    </link>
    <joint name="imu_joint" type="fixed">
        <parent link="trunk" />
        <child link="imu_link" />
        <origin rpy="0 0 0" xyz="-0.01592 -0.06659 -0.00617" />
    </joint>
    <link name="imu_link">
        <inertial>
            <mass value="0.001" />
            <origin rpy="0 0 0" xyz="0 0 0" />
            <inertia ixx="0.0001" ixy="0" ixz="0" iyy="0.0001" iyz="0" izz="0.0001" />
        </inertial>
        <visual>
            <origin rpy="0 0 0" xyz="0 0 0" />
            <geometry>
                <box size="0.001 0.001 0.001" />
            </geometry>
            <!-- <material name="red"/> -->
        </visual>
        <collision>
            <origin rpy="0 0 0" xyz="0 0 0" />
            <geometry>
                <box size=".001 .001 .001" />
            </geometry>
        </collision>
    </link>
    <joint name="base_to_trunk" type="fixed">
        <parent link="trunk" />
        <child link="base" />
        <origin rpy="0 0 1.5708" xyz="0 0 0.07" />
    </joint>
    <joint name="FR_hip_joint" type="revolute">
        <origin rpy="0 0 0" xyz="0.1934 -0.0465 0" />
        <parent link="trunk" />
        <child link="FR_hip" />
        <axis xyz="1 0 0" />
        <dynamics damping="0.0" friction="0.0" />
        <limit effort="23.7" lower="-1.0472" upper="1.0472" velocity="30.1" />
    </joint>
    <joint name="FR_hip_rotor_joint" type="fixed">
        <origin rpy="0 0 0" xyz="0.11215 -0.04675 0" />
        <parent link="trunk" />
        <child link="FR_hip_rotor" />
    </joint>
    <link name="FR_hip">
        <visual>
            <origin rpy="3.141592653589793 0 0" xyz="0 0 0" />
            <geometry>
                <mesh filename="package://go2_description/meshes/hip.dae" scale="1 1 1" />
            </geometry>
            <!-- <material name="orange"/> -->
        </visual>
        <collision>
            <origin rpy="1.5707963267948966 0 0" xyz="0 -0.0955 0" />
            <geometry>
                <cylinder length="0.04" radius="0.046" />
            </geometry>
        </collision>
        <inertial>
            <origin rpy="0 0 0" xyz="-0.0054 0.00194 -0.000105" />
            <mass value="0.678" />
            <inertia ixx="0.00048" ixy="3.01e-06" ixz="1.11e-06" iyy="0.000884" iyz="1.42e-06" izz="0.000596" />
        </inertial>
    </link>
    <link name="FR_hip_rotor">
        <visual>
            <origin rpy="0 1.5707963267948966 0" xyz="0 0 0" />
            <geometry>
                <cylinder length="0.02" radius="0.035" />
            </geometry>
            <material name="green" />
        </visual>
        <!-- <collision>
                <origin rpy="0 ${PI/2.0} 0" xyz="0 0 0"/>
                <geometry>
                    <cylinder length="0.02" radius="0.035"/>
                </geometry>
            </collision> -->
        <inertial>
            <origin rpy="0 0 0" xyz="0.0 0.0 0.0" />
            <mass value="0.089" />
            <inertia ixx="0.000111842" ixy="0.0" ixz="0.0" iyy="5.9647e-05" iyz="0.0" izz="5.9647e-05" />
        </inertial>
    </link>
    <joint name="FR_thigh_joint" type="revolute">
        <origin rpy="0 0 0" xyz="0 -0.0955 0" />
        <parent link="FR_hip" />
        <child link="FR_thigh" />
        <axis xyz="0 1 0" />
        <dynamics damping="0.0" friction="0.0" />
        <limit effort="23.7" lower="-1.5708" upper="3.4907" velocity="30.1" />
    </joint>
    <joint name="FR_thigh_rotor_joint" type="fixed">
        <origin rpy="0 0 0" xyz="0.0 0.00015 0" />
        <parent link="FR_hip" />
        <child link="FR_thigh_rotor" />
    </joint>
    <link name="FR_thigh">
        <visual>
            <origin rpy="0 0 0" xyz="0 0 0" />
            <geometry>
                <mesh filename="package://go2_description/meshes/thigh_mirror.dae" scale="1 1 1" />
            </geometry>
            <!-- <material name="orange"/> -->
        </visual>
        <collision>
            <origin rpy="0 1.5707963267948966 0" xyz="0 0 -0.1065" />
            <geometry>
                <box size="0.213 0.0245 0.034" />
            </geometry>
        </collision>
        <inertial>
            <origin rpy="0 0 0" xyz="-0.00374 0.0223 -0.0327" />
            <mass value="1.152" />
            <inertia ixx="0.00584" ixy="-8.72e-05" ixz="-0.000289" iyy="0.0058" iyz="-0.000808" izz="0.00103" />
        </inertial>
    </link>
    <link name="FR_thigh_rotor">
        <visual>
            <origin rpy="1.5707963267948966 0 0" xyz="0 0 0" />
            <geometry>
                <cylinder length="0.02" radius="0.035" />
            </geometry>
            <material name="green" />
        </visual>
        <!-- <collision>
                <origin rpy="${PI/2.0} 0 0" xyz="0 0 0"/>
                <geometry>
                    <cylinder length="0.02" radius="0.035"/>
                </geometry>
            </collision> -->
        <inertial>
            <origin rpy="0 0 0" xyz="0.0 0.0 0.0" />
            <mass value="0.089" />
            <inertia ixx="5.9647e-05" ixy="0.0" ixz="0.0" iyy="0.000111842" iyz="0.0" izz="5.9647e-05" />
        </inertial>
    </link>
    <joint name="FR_calf_joint" type="revolute">
        <origin rpy="0 0 0" xyz="0 0 -0.213" />
        <parent link="FR_thigh" />
        <child link="FR_calf" />
        <axis xyz="0 1 0" />
        <dynamics damping="0.0" friction="0.0" />
        <limit effort="35.55" lower="-2.7227" upper="-0.83776" velocity="20.06" />
    </joint>
    <joint name="FR_calf_rotor_joint" type="fixed">
        <origin rpy="0 0 0" xyz="0.0 0.03235 0" />
        <parent link="FR_thigh" />
        <child link="FR_calf_rotor" />
    </joint>
    <link name="FR_calf">
        <visual>
            <origin rpy="0 0 0" xyz="0 0 0" />
            <geometry>
                <mesh filename="package://go2_description/meshes/calf.dae" scale="1 1 1" />
            </geometry>
            <!-- <material name="orange"/> -->
        </visual>
        <collision>
            <origin rpy="0 1.5707963267948966 0" xyz="0 0 -0.1065" />
            <geometry>
                <box size="0.213 0.016 0.016" />
            </geometry>
        </collision>
        <inertial>
            <origin rpy="0 0 0" xyz="0.00548 -0.000975 -0.115" />
            <mass value="0.154" />
            <inertia ixx="0.00108" ixy="3.4e-07" ixz="1.72e-05" iyy="0.0011" iyz="8.28e-06" izz="3.29e-05" />
        </inertial>
    </link>
    <link name="FR_calf_rotor">
        <visual>
            <origin rpy="1.5707963267948966 0 0" xyz="0 0 0" />
            <geometry>
                <cylinder length="0.02" radius="0.035" />
            </geometry>
            <material name="green" />
        </visual>
        <!-- <collision>
                <origin rpy="${PI/2.0} 0 0" xyz="0 0 0"/>
                <geometry>
                    <cylinder length="0.02" radius="0.035"/>
                </geometry>
            </collision> -->
        <inertial>
            <origin rpy="0 0 0" xyz="0.0 0.0 0.0" />
            <mass value="0.089" />
            <inertia ixx="5.9647e-05" ixy="0.0" ixz="0.0" iyy="0.000111842" iyz="0.0" izz="5.9647e-05" />
        </inertial>
    </link>
    <joint name="FR_foot_fixed" type="fixed">
        <origin rpy="0 0 0" xyz="0 0 -0.213" />
        <parent link="FR_calf" />
        <child link="FR_foot" />
    </joint>
    <link name="FR_foot">
        <visual>
            <origin rpy="0 0 0" xyz="0 0 0" />
            <geometry>
                <sphere radius="0.01" />
            </geometry>
            <!-- <material name="orange"/> -->
        </visual>
        <collision>
            <origin rpy="0 0 0" xyz="0 0 0" />
            <geometry>
                <sphere radius="0.02" />
            </geometry>
        </collision>
        <inertial>
            <mass value="0.06" />
            <inertia ixx="9.600000000000001e-06" ixy="0.0" ixz="0.0" iyy="9.600000000000001e-06" iyz="0.0" izz="9.600000000000001e-06" />
            <origin xyz="0 0 0" rpy="0 0 0" />
        </inertial>
    </link>
    <transmission name="FR_hip_tran">
        <type>transmission_interface/SimpleTransmission</type>
        <joint name="FR_hip_joint">
            <hardwareInterface>hardware_interface/EffortJointInterface</hardwareInterface>
        </joint>
        <actuator name="FR_hip_motor">
            <hardwareInterface>hardware_interface/EffortJointInterface</hardwareInterface>
            <mechanicalReduction>1</mechanicalReduction>
        </actuator>
    </transmission>
    <transmission name="FR_thigh_tran">
        <type>transmission_interface/SimpleTransmission</type>
        <joint name="FR_thigh_joint">
            <hardwareInterface>hardware_interface/EffortJointInterface</hardwareInterface>
        </joint>
        <actuator name="FR_thigh_motor">
            <hardwareInterface>hardware_interface/EffortJointInterface</hardwareInterface>
            <mechanicalReduction>1</mechanicalReduction>
        </actuator>
    </transmission>
    <transmission name="FR_calf_tran">
        <type>transmission_interface/SimpleTransmission</type>
        <joint name="FR_calf_joint">
            <hardwareInterface>hardware_interface/EffortJointInterface</hardwareInterface>
        </joint>
        <actuator name="FR_calf_motor">
            <hardwareInterface>hardware_interface/EffortJointInterface</hardwareInterface>
            <mechanicalReduction>1</mechanicalReduction>
        </actuator>
    </transmission>
    <joint name="FL_hip_joint" type="revolute">
        <origin rpy="0 0 0" xyz="0.1934 0.0465 0" />
        <parent link="trunk" />
        <child link="FL_hip" />
        <axis xyz="1 0 0" />
        <dynamics damping="0.0" friction="0.0" />
        <limit effort="23.7" lower="-1.0472" upper="1.0472" velocity="30.1" />
    </joint>
    <joint name="FL_hip_rotor_joint" type="fixed">
        <origin rpy="0 0 0" xyz="0.11215 0.04675 0" />
        <parent link="trunk" />
        <child link="FL_hip_rotor" />
    </joint>
    <link name="FL_hip">
        <visual>
            <origin rpy="0 0 0" xyz="0 0 0" />
            <geometry>
                <mesh filename="package://go2_description/meshes/hip.dae" scale="1 1 1" />
            </geometry>
            <!-- <material name="orange"/> -->
        </visual>
        <collision>
            <origin rpy="1.5707963267948966 0 0" xyz="0 0.0955 0" />
            <geometry>
                <cylinder length="0.04" radius="0.046" />
            </geometry>
        </collision>
        <inertial>
            <origin rpy="0 0 0" xyz="-0.0054 -0.00194 -0.000105" />
            <mass value="0.678" />
            <inertia ixx="0.00048" ixy="-3.01e-06" ixz="1.11e-06" iyy="0.000884" iyz="-1.42e-06" izz="0.000596" />
        </inertial>
    </link>
    <link name="FL_hip_rotor">
        <visual>
            <origin rpy="0 1.5707963267948966 0" xyz="0 0 0" />
            <geometry>
                <cylinder length="0.02" radius="0.035" />
            </geometry>
            <material name="green" />
        </visual>
        <!-- <collision>
                <origin rpy="0 ${PI/2.0} 0" xyz="0 0 0"/>
                <geometry>
                    <cylinder length="0.02" radius="0.035"/>
                </geometry>
            </collision> -->
        <inertial>
            <origin rpy="0 0 0" xyz="0.0 0.0 0.0" />
            <mass value="0.089" />
            <inertia ixx="0.000111842" ixy="0.0" ixz="0.0" iyy="5.9647e-05" iyz="0.0" izz="5.9647e-05" />
        </inertial>
    </link>
    <joint name="FL_thigh_joint" type="revolute">
        <origin rpy="0 0 0" xyz="0 0.0955 0" />
        <parent link="FL_hip" />
        <child link="FL_thigh" />
        <axis xyz="0 1 0" />
        <dynamics damping="0.0" friction="0.0" />
        <limit effort="23.7" lower="-1.5708" upper="3.4907" velocity="30.1" />
    </joint>
    <joint name="FL_thigh_rotor_joint" type="fixed">
        <origin rpy="0 0 0" xyz="0.0 -0.00015 0" />
        <parent link="FL_hip" />
        <child link="FL_thigh_rotor" />
    </joint>
    <link name="FL_thigh">
        <visual>
            <origin rpy="0 0 0" xyz="0 0 0" />
            <geometry>
                <mesh filename="package://go2_description/meshes/thigh.dae" scale="1 1 1" />
            </geometry>
            <!-- <material name="orange"/> -->
        </visual>
        <collision>
            <origin rpy="0 1.5707963267948966 0" xyz="0 0 -0.1065" />
            <geometry>
                <box size="0.213 0.0245 0.034" />
            </geometry>
        </collision>
        <inertial>
            <origin rpy="0 0 0" xyz="-0.00374 -0.0223 -0.0327" />
            <mass value="1.152" />
            <inertia ixx="0.00584" ixy="8.72e-05" ixz="-0.000289" iyy="0.0058" iyz="0.000808" izz="0.00103" />
        </inertial>
    </link>
    <link name="FL_thigh_rotor">
        <visual>
            <origin rpy="1.5707963267948966 0 0" xyz="0 0 0" />
            <geometry>
                <cylinder length="0.02" radius="0.035" />
            </geometry>
            <material name="green" />
        </visual>
        <!-- <collision>
                <origin rpy="${PI/2.0} 0 0" xyz="0 0 0"/>
                <geometry>
                    <cylinder length="0.02" radius="0.035"/>
                </geometry>
            </collision> -->
        <inertial>
            <origin rpy="0 0 0" xyz="0.0 0.0 0.0" />
            <mass value="0.089" />
            <inertia ixx="5.9647e-05" ixy="0.0" ixz="0.0" iyy="0.000111842" iyz="0.0" izz="5.9647e-05" />
        </inertial>
    </link>
    <joint name="FL_calf_joint" type="revolute">
        <origin rpy="0 0 0" xyz="0 0 -0.213" />
        <parent link="FL_thigh" />
        <child link="FL_calf" />
        <axis xyz="0 1 0" />
        <dynamics damping="0.0" friction="0.0" />
        <limit effort="35.55" lower="-2.7227" upper="-0.83776" velocity="20.06" />
    </joint>
    <joint name="FL_calf_rotor_joint" type="fixed">
        <origin rpy="0 0 0" xyz="0.0 -0.03235 0" />
        <parent link="FL_thigh" />
        <child link="FL_calf_rotor" />
    </joint>
    <link name="FL_calf">
        <visual>
            <origin rpy="0 0 0" xyz="0 0 0" />
            <geometry>
                <mesh filename="package://go2_description/meshes/calf.dae" scale="1 1 1" />
            </geometry>
            <!-- <material name="orange"/> -->
        </visual>
        <collision>
            <origin rpy="0 1.5707963267948966 0" xyz="0 0 -0.1065" />
            <geometry>
                <box size="0.213 0.016 0.016" />
            </geometry>
        </collision>
        <inertial>
            <origin rpy="0 0 0" xyz="0.00548 -0.000975 -0.115" />
            <mass value="0.154" />
            <inertia ixx="0.00108" ixy="3.4e-07" ixz="1.72e-05" iyy="0.0011" iyz="8.28e-06" izz="3.29e-05" />
        </inertial>
    </link>
    <link name="FL_calf_rotor">
        <visual>
            <origin rpy="1.5707963267948966 0 0" xyz="0 0 0" />
            <geometry>
                <cylinder length="0.02" radius="0.035" />
            </geometry>
            <material name="green" />
        </visual>
        <!-- <collision>
                <origin rpy="${PI/2.0} 0 0" xyz="0 0 0"/>
                <geometry>
                    <cylinder length="0.02" radius="0.035"/>
                </geometry>
            </collision> -->
        <inertial>
            <origin rpy="0 0 0" xyz="0.0 0.0 0.0" />
            <mass value="0.089" />
            <inertia ixx="5.9647e-05" ixy="0.0" ixz="0.0" iyy="0.000111842" iyz="0.0" izz="5.9647e-05" />
        </inertial>
    </link>
    <joint name="FL_foot_fixed" type="fixed">
        <origin rpy="0 0 0" xyz="0 0 -0.213" />
        <parent link="FL_calf" />
        <child link="FL_foot" />
    </joint>
    <link name="FL_foot">
        <visual>
            <origin rpy="0 0 0" xyz="0 0 0" />
            <geometry>
                <sphere radius="0.01" />
            </geometry>
            <!-- <material name="orange"/> -->
        </visual>
        <collision>
            <origin rpy="0 0 0" xyz="0 0 0" />
            <geometry>
                <sphere radius="0.02" />
            </geometry>
        </collision>
        <inertial>
            <mass value="0.06" />
            <inertia ixx="9.600000000000001e-06" ixy="0.0" ixz="0.0" iyy="9.600000000000001e-06" iyz="0.0" izz="9.600000000000001e-06" />
            <origin xyz="0 0 0" rpy="0 0 0" />
        </inertial>
    </link>
    <transmission name="FL_hip_tran">
        <type>transmission_interface/SimpleTransmission</type>
        <joint name="FL_hip_joint">
            <hardwareInterface>hardware_interface/EffortJointInterface</hardwareInterface>
        </joint>
        <actuator name="FL_hip_motor">
            <hardwareInterface>hardware_interface/EffortJointInterface</hardwareInterface>
            <mechanicalReduction>1</mechanicalReduction>
        </actuator>
    </transmission>
    <transmission name="FL_thigh_tran">
        <type>transmission_interface/SimpleTransmission</type>
        <joint name="FL_thigh_joint">
            <hardwareInterface>hardware_interface/EffortJointInterface</hardwareInterface>
        </joint>
        <actuator name="FL_thigh_motor">
            <hardwareInterface>hardware_interface/EffortJointInterface</hardwareInterface>
            <mechanicalReduction>1</mechanicalReduction>
        </actuator>
    </transmission>
    <transmission name="FL_calf_tran">
        <type>transmission_interface/SimpleTransmission</type>
        <joint name="FL_calf_joint">
            <hardwareInterface>hardware_interface/EffortJointInterface</hardwareInterface>
        </joint>
        <actuator name="FL_calf_motor">
            <hardwareInterface>hardware_interface/EffortJointInterface</hardwareInterface>
            <mechanicalReduction>1</mechanicalReduction>
        </actuator>
    </transmission>
    <joint name="RR_hip_joint" type="revolute">
        <origin rpy="0 0 0" xyz="-0.1934 -0.0465 0" />
        <parent link="trunk" />
        <child link="RR_hip" />
        <axis xyz="1 0 0" />
        <dynamics damping="0.0" friction="0.0" />
        <limit effort="23.7" lower="-1.0472" upper="1.0472" velocity="30.1" />
    </joint>
    <joint name="RR_hip_rotor_joint" type="fixed">
        <origin rpy="0 0 0" xyz="-0.11215 -0.04675 0" />
        <parent link="trunk" />
        <child link="RR_hip_rotor" />
    </joint>
    <link name="RR_hip">
        <visual>
            <origin rpy="3.141592653589793 3.141592653589793 0" xyz="0 0 0" />
            <geometry>
                <mesh filename="package://go2_description/meshes/hip.dae" scale="1 1 1" />
            </geometry>
            <!-- <material name="orange"/> -->
        </visual>
        <collision>
            <origin rpy="1.5707963267948966 0 0" xyz="0 -0.0955 0" />
            <geometry>
                <cylinder length="0.04" radius="0.046" />
            </geometry>
        </collision>
        <inertial>
            <origin rpy="0 0 0" xyz="0.0054 0.00194 -0.000105" />
            <mass value="0.678" />
            <inertia ixx="0.00048" ixy="-3.01e-06" ixz="-1.11e-06" iyy="0.000884" iyz="1.42e-06" izz="0.000596" />
        </inertial>
    </link>
    <link name="RR_hip_rotor">
        <visual>
            <origin rpy="0 1.5707963267948966 0" xyz="0 0 0" />
            <geometry>
                <cylinder length="0.02" radius="0.035" />
            </geometry>
            <material name="green" />
        </visual>
        <!-- <collision>
                <origin rpy="0 ${PI/2.0} 0" xyz="0 0 0"/>
                <geometry>
                    <cylinder length="0.02" radius="0.035"/>
                </geometry>
            </collision> -->
        <inertial>
            <origin rpy="0 0 0" xyz="0.0 0.0 0.0" />
            <mass value="0.089" />
            <inertia ixx="0.000111842" ixy="0.0" ixz="0.0" iyy="5.9647e-05" iyz="0.0" izz="5.9647e-05" />
        </inertial>
    </link>
    <joint name="RR_thigh_joint" type="revolute">
        <origin rpy="0 0 0" xyz="0 -0.0955 0" />
        <parent link="RR_hip" />
        <child link="RR_thigh" />
        <axis xyz="0 1 0" />
        <dynamics damping="0.0" friction="0.0" />
        <limit effort="23.7" lower="-1.5708" upper="3.4907" velocity="30.1" />
    </joint>
    <joint name="RR_thigh_rotor_joint" type="fixed">
        <origin rpy="0 0 0" xyz="0.0 0.00015 0" />
        <parent link="RR_hip" />
        <child link="RR_thigh_rotor" />
    </joint>
    <link name="RR_thigh">
        <visual>
            <origin rpy="0 0 0" xyz="0 0 0" />
            <geometry>
                <mesh filename="package://go2_description/meshes/thigh_mirror.dae" scale="1 1 1" />
            </geometry>
            <!-- <material name="orange"/> -->
        </visual>
        <collision>
            <origin rpy="0 1.5707963267948966 0" xyz="0 0 -0.1065" />
            <geometry>
                <box size="0.213 0.0245 0.034" />
            </geometry>
        </collision>
        <inertial>
            <origin rpy="0 0 0" xyz="-0.00374 0.0223 -0.0327" />
            <mass value="1.152" />
            <inertia ixx="0.00584" ixy="-8.72e-05" ixz="-0.000289" iyy="0.0058" iyz="-0.000808" izz="0.00103" />
        </inertial>
    </link>
    <link name="RR_thigh_rotor">
        <visual>
            <origin rpy="1.5707963267948966 0 0" xyz="0 0 0" />
            <geometry>
                <cylinder length="0.02" radius="0.035" />
            </geometry>
            <material name="green" />
        </visual>
        <!-- <collision>
                <origin rpy="${PI/2.0} 0 0" xyz="0 0 0"/>
                <geometry>
                    <cylinder length="0.02" radius="0.035"/>
                </geometry>
            </collision> -->
        <inertial>
            <origin rpy="0 0 0" xyz="0.0 0.0 0.0" />
            <mass value="0.089" />
            <inertia ixx="5.9647e-05" ixy="0.0" ixz="0.0" iyy="0.000111842" iyz="0.0" izz="5.9647e-05" />
        </inertial>
    </link>
    <joint name="RR_calf_joint" type="revolute">
        <origin rpy="0 0 0" xyz="0 0 -0.213" />
        <parent link="RR_thigh" />
        <child link="RR_calf" />
        <axis xyz="0 1 0" />
        <dynamics damping="0.0" friction="0.0" />
        <limit effort="35.55" lower="-2.7227" upper="-0.83776" velocity="20.06" />
    </joint>
    <joint name="RR_calf_rotor_joint" type="fixed">
        <origin rpy="0 0 0" xyz="0.0 0.03235 0" />
        <parent link="RR_thigh" />
        <child link="RR_calf_rotor" />
    </joint>
    <link name="RR_calf">
        <visual>
            <origin rpy="0 0 0" xyz="0 0 0" />
            <geometry>
                <mesh filename="package://go2_description/meshes/calf.dae" scale="1 1 1" />
            </geometry>
            <!-- <material name="orange"/> -->
        </visual>
        <collision>
            <origin rpy="0 1.5707963267948966 0" xyz="0 0 -0.1065" />
            <geometry>
                <box size="0.213 0.016 0.016" />
            </geometry>
        </collision>
        <inertial>
            <origin rpy="0 0 0" xyz="0.00548 -0.000975 -0.115" />
            <mass value="0.154" />
            <inertia ixx="0.00108" ixy="3.4e-07" ixz="1.72e-05" iyy="0.0011" iyz="8.28e-06" izz="3.29e-05" />
        </inertial>
    </link>
    <link name="RR_calf_rotor">
        <visual>
            <origin rpy="1.5707963267948966 0 0" xyz="0 0 0" />
            <geometry>
                <cylinder length="0.02" radius="0.035" />
            </geometry>
            <material name="green" />
        </visual>
        <!-- <collision>
                <origin rpy="${PI/2.0} 0 0" xyz="0 0 0"/>
                <geometry>
                    <cylinder length="0.02" radius="0.035"/>
                </geometry>
            </collision> -->
        <inertial>
            <origin rpy="0 0 0" xyz="0.0 0.0 0.0" />
            <mass value="0.089" />
            <inertia ixx="5.9647e-05" ixy="0.0" ixz="0.0" iyy="0.000111842" iyz="0.0" izz="5.9647e-05" />
        </inertial>
    </link>
    <joint name="RR_foot_fixed" type="fixed">
        <origin rpy="0 0 0" xyz="0 0 -0.213" />
        <parent link="RR_calf" />
        <child link="RR_foot" />
    </joint>
    <link name="RR_foot">
        <visual>
            <origin rpy="0 0 0" xyz="0 0 0" />
            <geometry>
                <sphere radius="0.01" />
            </geometry>
            <!-- <material name="orange"/> -->
        </visual>
        <collision>
            <origin rpy="0 0 0" xyz="0 0 0" />
            <geometry>
                <sphere radius="0.02" />
            </geometry>
        </collision>
        <inertial>
            <mass value="0.06" />
            <inertia ixx="9.600000000000001e-06" ixy="0.0" ixz="0.0" iyy="9.600000000000001e-06" iyz="0.0" izz="9.600000000000001e-06" />
            <origin xyz="0 0 0" rpy="0 0 0" />
        </inertial>
    </link>
    <transmission name="RR_hip_tran">
        <type>transmission_interface/SimpleTransmission</type>
        <joint name="RR_hip_joint">
            <hardwareInterface>hardware_interface/EffortJointInterface</hardwareInterface>
        </joint>
        <actuator name="RR_hip_motor">
            <hardwareInterface>hardware_interface/EffortJointInterface</hardwareInterface>
            <mechanicalReduction>1</mechanicalReduction>
        </actuator>
    </transmission>
    <transmission name="RR_thigh_tran">
        <type>transmission_interface/SimpleTransmission</type>
        <joint name="RR_thigh_joint">
            <hardwareInterface>hardware_interface/EffortJointInterface</hardwareInterface>
        </joint>
        <actuator name="RR_thigh_motor">
            <hardwareInterface>hardware_interface/EffortJointInterface</hardwareInterface>
            <mechanicalReduction>1</mechanicalReduction>
        </actuator>
    </transmission>
    <transmission name="RR_calf_tran">
        <type>transmission_interface/SimpleTransmission</type>
        <joint name="RR_calf_joint">
            <hardwareInterface>hardware_interface/EffortJointInterface</hardwareInterface>
        </joint>
        <actuator name="RR_calf_motor">
            <hardwareInterface>hardware_interface/EffortJointInterface</hardwareInterface>
            <mechanicalReduction>1</mechanicalReduction>
        </actuator>
    </transmission>
    <joint name="RL_hip_joint" type="revolute">
        <origin rpy="0 0 0" xyz="-0.1934 0.0465 0" />
        <parent link="trunk" />
        <child link="RL_hip" />
        <axis xyz="1 0 0" />
        <dynamics damping="0.0" friction="0.0" />
        <limit effort="23.7" lower="-1.0472" upper="1.0472" velocity="30.1" />
    </joint>
    <joint name="RL_hip_rotor_joint" type="fixed">
        <origin rpy="0 0 0" xyz="-0.11215 0.04675 0" />
        <parent link="trunk" />
        <child link="RL_hip_rotor" />
    </joint>
    <link name="RL_hip">
        <visual>
            <origin rpy="0 3.141592653589793 0" xyz="0 0 0" />
            <geometry>
                <mesh filename="package://go2_description/meshes/hip.dae" scale="1 1 1" />
            </geometry>
            <!-- <material name="orange"/> -->
        </visual>
        <collision>
            <origin rpy="1.5707963267948966 0 0" xyz="0 0.0955 0" />
            <geometry>
                <cylinder length="0.04" radius="0.046" />
            </geometry>
        </collision>
        <inertial>
            <origin rpy="0 0 0" xyz="0.0054 -0.00194 -0.000105" />
            <mass value="0.678" />
            <inertia ixx="0.00048" ixy="3.01e-06" ixz="-1.11e-06" iyy="0.000884" iyz="-1.42e-06" izz="0.000596" />
        </inertial>
    </link>
    <link name="RL_hip_rotor">
        <visual>
            <origin rpy="0 1.5707963267948966 0" xyz="0 0 0" />
            <geometry>
                <cylinder length="0.02" radius="0.035" />
            </geometry>
            <material name="green" />
        </visual>
        <!-- <collision>
                <origin rpy="0 ${PI/2.0} 0" xyz="0 0 0"/>
                <geometry>
                    <cylinder length="0.02" radius="0.035"/>
                </geometry>
            </collision> -->
        <inertial>
            <origin rpy="0 0 0" xyz="0.0 0.0 0.0" />
            <mass value="0.089" />
            <inertia ixx="0.000111842" ixy="0.0" ixz="0.0" iyy="5.9647e-05" iyz="0.0" izz="5.9647e-05" />
        </inertial>
    </link>
    <joint name="RL_thigh_joint" type="revolute">
        <origin rpy="0 0 0" xyz="0 0.0955 0" />
        <parent link="RL_hip" />
        <child link="RL_thigh" />
        <axis xyz="0 1 0" />
        <dynamics damping="0.0" friction="0.0" />
        <limit effort="23.7" lower="-1.5708" upper="3.4907" velocity="30.1" />
    </joint>
    <joint name="RL_thigh_rotor_joint" type="fixed">
        <origin rpy="0 0 0" xyz="0.0 -0.00015 0" />
        <parent link="RL_hip" />
        <child link="RL_thigh_rotor" />
    </joint>
    <link name="RL_thigh">
        <visual>
            <origin rpy="0 0 0" xyz="0 0 0" />
            <geometry>
                <mesh filename="package://go2_description/meshes/thigh.dae" scale="1 1 1" />
            </geometry>
            <!-- <material name="orange"/> -->
        </visual>
        <collision>
            <origin rpy="0 1.5707963267948966 0" xyz="0 0 -0.1065" />
            <geometry>
                <box size="0.213 0.0245 0.034" />
            </geometry>
        </collision>
        <inertial>
            <origin rpy="0 0 0" xyz="-0.00374 -0.0223 -0.0327" />
            <mass value="1.152" />
            <inertia ixx="0.00584" ixy="8.72e-05" ixz="-0.000289" iyy="0.0058" iyz="0.000808" izz="0.00103" />
        </inertial>
    </link>
    <link name="RL_thigh_rotor">
        <visual>
            <origin rpy="1.5707963267948966 0 0" xyz="0 0 0" />
            <geometry>
                <cylinder length="0.02" radius="0.035" />
            </geometry>
            <material name="green" />
        </visual>
        <!-- <collision>
                <origin rpy="${PI/2.0} 0 0" xyz="0 0 0"/>
                <geometry>
                    <cylinder length="0.02" radius="0.035"/>
                </geometry>
            </collision> -->
        <inertial>
            <origin rpy="0 0 0" xyz="0.0 0.0 0.0" />
            <mass value="0.089" />
            <inertia ixx="5.9647e-05" ixy="0.0" ixz="0.0" iyy="0.000111842" iyz="0.0" izz="5.9647e-05" />
        </inertial>
    </link>
    <joint name="RL_calf_joint" type="revolute">
        <origin rpy="0 0 0" xyz="0 0 -0.213" />
        <parent link="RL_thigh" />
        <child link="RL_calf" />
        <axis xyz="0 1 0" />
        <dynamics damping="0.0" friction="0.0" />
        <limit effort="35.55" lower="-2.7227" upper="-0.83776" velocity="20.06" />
    </joint>
    <joint name="RL_calf_rotor_joint" type="fixed">
        <origin rpy="0 0 0" xyz="0.0 -0.03235 0" />
        <parent link="RL_thigh" />
        <child link="RL_calf_rotor" />
    </joint>
    <link name="RL_calf">
        <visual>
            <origin rpy="0 0 0" xyz="0 0 0" />
            <geometry>
                <mesh filename="package://go2_description/meshes/calf.dae" scale="1 1 1" />
            </geometry>
            <!-- <material name="orange"/> -->
        </visual>
        <collision>
            <origin rpy="0 1.5707963267948966 0" xyz="0 0 -0.1065" />
            <geometry>
                <box size="0.213 0.016 0.016" />
            </geometry>
        </collision>
        <inertial>
            <origin rpy="0 0 0" xyz="0.00548 -0.000975 -0.115" />
            <mass value="0.154" />
            <inertia ixx="0.00108" ixy="3.4e-07" ixz="1.72e-05" iyy="0.0011" iyz="8.28e-06" izz="3.29e-05" />
        </inertial>
    </link>
    <link name="RL_calf_rotor">
        <visual>
            <origin rpy="1.5707963267948966 0 0" xyz="0 0 0" />
            <geometry>
                <cylinder length="0.02" radius="0.035" />
            </geometry>
            <material name="green" />
        </visual>
        <!-- <collision>
                <origin rpy="${PI/2.0} 0 0" xyz="0 0 0"/>
                <geometry>
                    <cylinder length="0.02" radius="0.035"/>
                </geometry>
            </collision> -->
        <inertial>
            <origin rpy="0 0 0" xyz="0.0 0.0 0.0" />
            <mass value="0.089" />
            <inertia ixx="5.9647e-05" ixy="0.0" ixz="0.0" iyy="0.000111842" iyz="0.0" izz="5.9647e-05" />
        </inertial>
    </link>
    <joint name="RL_foot_fixed" type="fixed">
        <origin rpy="0 0 0" xyz="0 0 -0.213" />
        <parent link="RL_calf" />
        <child link="RL_foot" />
    </joint>
    <link name="RL_foot">
        <visual>
            <origin rpy="0 0 0" xyz="0 0 0" />
            <geometry>
                <sphere radius="0.01" />
            </geometry>
            <!-- <material name="orange"/> -->
        </visual>
        <collision>
            <origin rpy="0 0 0" xyz="0 0 0" />
            <geometry>
                <sphere radius="0.02" />
            </geometry>
        </collision>
        <inertial>
            <mass value="0.06" />
            <inertia ixx="9.600000000000001e-06" ixy="0.0" ixz="0.0" iyy="9.600000000000001e-06" iyz="0.0" izz="9.600000000000001e-06" />
            <origin xyz="0 0 0" rpy="0 0 0" />
        </inertial>
    </link>
    <transmission name="RL_hip_tran">
        <type>transmission_interface/SimpleTransmission</type>
        <joint name="RL_hip_joint">
            <hardwareInterface>hardware_interface/EffortJointInterface</hardwareInterface>
        </joint>
        <actuator name="RL_hip_motor">
            <hardwareInterface>hardware_interface/EffortJointInterface</hardwareInterface>
            <mechanicalReduction>1</mechanicalReduction>
        </actuator>
    </transmission>
    <transmission name="RL_thigh_tran">
        <type>transmission_interface/SimpleTransmission</type>
        <joint name="RL_thigh_joint">
            <hardwareInterface>hardware_interface/EffortJointInterface</hardwareInterface>
        </joint>
        <actuator name="RL_thigh_motor">
            <hardwareInterface>hardware_interface/EffortJointInterface</hardwareInterface>
            <mechanicalReduction>1</mechanicalReduction>
        </actuator>
    </transmission>
    <transmission name="RL_calf_tran">
        <type>transmission_interface/SimpleTransmission</type>
        <joint name="RL_calf_joint">
            <hardwareInterface>hardware_interface/EffortJointInterface</hardwareInterface>
        </joint>
        <actuator name="RL_calf_motor">
            <hardwareInterface>hardware_interface/EffortJointInterface</hardwareInterface>
            <mechanicalReduction>1</mechanicalReduction>
        </actuator>
    </transmission>
    <joint name="camera_joint_face" type="fixed">
        <origin rpy="3.141592653589793 0 0" xyz="0.2785 0.0125 0.0167" />
        <parent link="trunk" />
        <child link="camera_face" />
    </joint>
    <link name="camera_face">
        <collision>
            <origin rpy="0 0 0" xyz="0 0 0" />
            <geometry>
                <box size=".001 .001 .001" />
            </geometry>
        </collision>
        <visual>
            <origin rpy="0 0 0" xyz="0 0 0" />
            <geometry>
                <mesh filename="package://go1_description/meshes/depthCamera.dae" scale="1 1 1" />
            </geometry>
        </visual>
        <inertial>
            <mass value="1e-5" />
            <origin rpy="0 0 0" xyz="0 0 0" />
            <inertia ixx="1e-6" ixy="0" ixz="0" iyy="1e-6" iyz="0" izz="1e-6" />
        </inertial>
    </link>
    <joint name="camera_optical_joint_face" type="fixed">
        <origin rpy="-1.5707963267948966 0 -1.5707963267948966" xyz="0 0 0" />
        <parent link="camera_face" />
        <child link="camera_optical_face" />
    </joint>
    <link name="camera_optical_face" />
    <gazebo reference="camera_face">
        <!-- <material>Gazebo/Black</material> -->
        <sensor name="camera_face_camera" type="depth">
            <update_rate>16</update_rate>
            <camera>
                <horizontal_fov>2.094</horizontal_fov>
                <image>
                    <width>928</width>
                    <height>800</height>
                    <format>R8G8B8</format>
                </image>
                <clip>
                    <near>0.1</near>
                    <far>5</far>
                </clip>
            </camera>
            <plugin filename="libgazebo_ros_openni_kinect.so" name="camera_face_controller">
                <baseline>0.025</baseline>
                <alwaysOn>true</alwaysOn>
                <updateRate>0.0</updateRate>
                <cameraName>camera_face_ir</cameraName>
                <imageTopicName>/camera_face/color/image_raw</imageTopicName>
                <cameraInfoTopicName>/camera_face/color/camera_info</cameraInfoTopicName>
                <depthImageTopicName>/camera_face/depth/image_raw</depthImageTopicName>
                <depthImageInfoTopicName>/camera_face/depth/camera_info</depthImageInfoTopicName>
                <!-- <pointCloudTopicName>/camera_${name}/depth/points</pointCloudTopicName> -->
                <pointCloudTopicName>/cam1/point_cloud_face</pointCloudTopicName>
                <frameName>camera_optical_face</frameName>
                <pointCloudCutoff>0.1</pointCloudCutoff>
                <pointCloudCutoffMax>1.5</pointCloudCutoffMax>
                <distortionK1>0.0</distortionK1>
                <distortionK2>0.0</distortionK2>
                <distortionK3>0.0</distortionK3>
                <distortionT1>0.0</distortionT1>
                <distortionT2>0.0</distortionT2>
                <CxPrime>0</CxPrime>
                <Cx>0.0045</Cx>
                <Cy>0.0039</Cy>
                <focalLength>0</focalLength>
                <hackBaseline>0</hackBaseline>
            </plugin>
        </sensor>
    </gazebo>
    <joint name="camera_joint_chin" type="fixed">
        <origin rpy="3.141592653589793 1.5707963267948966 0" xyz="0.2522 0.0125 -0.0436" />
        <parent link="trunk" />
        <child link="camera_chin" />
    </joint>
    <link name="camera_chin">
        <collision>
            <origin rpy="0 0 0" xyz="0 0 0" />
            <geometry>
                <box size=".001 .001 .001" />
            </geometry>
        </collision>
        <visual>
            <origin rpy="0 0 0" xyz="0 0 0" />
            <geometry>
                <mesh filename="package://go1_description/meshes/depthCamera.dae" scale="1 1 1" />
            </geometry>
        </visual>
        <inertial>
            <mass value="1e-5" />
            <origin rpy="0 0 0" xyz="0 0 0" />
            <inertia ixx="1e-6" ixy="0" ixz="0" iyy="1e-6" iyz="0" izz="1e-6" />
        </inertial>
    </link>
    <joint name="camera_optical_joint_chin" type="fixed">
        <origin rpy="-1.5707963267948966 0 -1.5707963267948966" xyz="0 0 0" />
        <parent link="camera_chin" />
        <child link="camera_optical_chin" />
    </joint>
    <link name="camera_optical_chin" />
    <gazebo reference="camera_chin">
        <!-- <material>Gazebo/Black</material> -->
        <sensor name="camera_chin_camera" type="depth">
            <update_rate>16</update_rate>
            <camera>
                <horizontal_fov>2.094</horizontal_fov>
                <image>
                    <width>928</width>
                    <height>800</height>
                    <format>R8G8B8</format>
                </image>
                <clip>
                    <near>0.1</near>
                    <far>5</far>
                </clip>
            </camera>
            <plugin filename="libgazebo_ros_openni_kinect.so" name="camera_chin_controller">
                <baseline>0.025</baseline>
                <alwaysOn>true</alwaysOn>
                <updateRate>0.0</updateRate>
                <cameraName>camera_chin_ir</cameraName>
                <imageTopicName>/camera_chin/color/image_raw</imageTopicName>
                <cameraInfoTopicName>/camera_chin/color/camera_info</cameraInfoTopicName>
                <depthImageTopicName>/camera_chin/depth/image_raw</depthImageTopicName>
                <depthImageInfoTopicName>/camera_chin/depth/camera_info</depthImageInfoTopicName>
                <!-- <pointCloudTopicName>/camera_${name}/depth/points</pointCloudTopicName> -->
                <pointCloudTopicName>/cam2/point_cloud_chin</pointCloudTopicName>
                <frameName>camera_optical_chin</frameName>
                <pointCloudCutoff>0.1</pointCloudCutoff>
                <pointCloudCutoffMax>1.5</pointCloudCutoffMax>
                <distortionK1>0.0</distortionK1>
                <distortionK2>0.0</distortionK2>
                <distortionK3>0.0</distortionK3>
                <distortionT1>0.0</distortionT1>
                <distortionT2>0.0</distortionT2>
                <CxPrime>0</CxPrime>
                <Cx>0.0045</Cx>
                <Cy>0.0039</Cy>
                <focalLength>0</focalLength>
                <hackBaseline>0</hackBaseline>
            </plugin>
        </sensor>
    </gazebo>
    <joint name="camera_joint_left" type="fixed">
        <origin rpy="3.141592653589793 0.2618 1.5707963267948966" xyz="-0.066 0.082 -0.0176" />
        <parent link="trunk" />
        <child link="camera_left" />
    </joint>
    <link name="camera_left">
        <collision>
            <origin rpy="0 0 0" xyz="0 0 0" />
            <geometry>
                <box size=".001 .001 .001" />
            </geometry>
        </collision>
        <visual>
            <origin rpy="0 0 0" xyz="0 0 0" />
            <geometry>
                <mesh filename="package://go1_description/meshes/depthCamera.dae" scale="1 1 1" />
            </geometry>
        </visual>
        <inertial>
            <mass value="1e-5" />
            <origin rpy="0 0 0" xyz="0 0 0" />
            <inertia ixx="1e-6" ixy="0" ixz="0" iyy="1e-6" iyz="0" izz="1e-6" />
        </inertial>
    </link>
    <joint name="camera_optical_joint_left" type="fixed">
        <origin rpy="-1.5707963267948966 0 -1.5707963267948966" xyz="0 0 0" />
        <parent link="camera_left" />
        <child link="camera_optical_left" />
    </joint>
    <link name="camera_optical_left" />
    <gazebo reference="camera_left">
        <!-- <material>Gazebo/Black</material> -->
        <sensor name="camera_left_camera" type="depth">
            <update_rate>16</update_rate>
            <camera>
                <horizontal_fov>2.094</horizontal_fov>
                <image>
                    <width>928</width>
                    <height>800</height>
                    <format>R8G8B8</format>
                </image>
                <clip>
                    <near>0.1</near>
                    <far>5</far>
                </clip>
            </camera>
            <plugin filename="libgazebo_ros_openni_kinect.so" name="camera_left_controller">
                <baseline>0.025</baseline>
                <alwaysOn>true</alwaysOn>
                <updateRate>0.0</updateRate>
                <cameraName>camera_left_ir</cameraName>
                <imageTopicName>/camera_left/color/image_raw</imageTopicName>
                <cameraInfoTopicName>/camera_left/color/camera_info</cameraInfoTopicName>
                <depthImageTopicName>/camera_left/depth/image_raw</depthImageTopicName>
                <depthImageInfoTopicName>/camera_left/depth/camera_info</depthImageInfoTopicName>
                <!-- <pointCloudTopicName>/camera_${name}/depth/points</pointCloudTopicName> -->
                <pointCloudTopicName>/cam3/point_cloud_left</pointCloudTopicName>
                <frameName>camera_optical_left</frameName>
                <pointCloudCutoff>0.1</pointCloudCutoff>
                <pointCloudCutoffMax>1.5</pointCloudCutoffMax>
                <distortionK1>0.0</distortionK1>
                <distortionK2>0.0</distortionK2>
                <distortionK3>0.0</distortionK3>
                <distortionT1>0.0</distortionT1>
                <distortionT2>0.0</distortionT2>
                <CxPrime>0</CxPrime>
                <Cx>0.0045</Cx>
                <Cy>0.0039</Cy>
                <focalLength>0</focalLength>
                <hackBaseline>0</hackBaseline>
            </plugin>
        </sensor>
    </gazebo>
    <joint name="camera_joint_right" type="fixed">
        <origin rpy="3.141592653589793 0.2618 -1.5707963267948966" xyz="-0.041 -0.082 -0.0176" />
        <parent link="trunk" />
        <child link="camera_right" />
    </joint>
    <link name="camera_right">
        <collision>
            <origin rpy="0 0 0" xyz="0 0 0" />
            <geometry>
                <box size=".001 .001 .001" />
            </geometry>
        </collision>
        <visual>
            <origin rpy="0 0 0" xyz="0 0 0" />
            <geometry>
                <mesh filename="package://go1_description/meshes/depthCamera.dae" scale="1 1 1" />
            </geometry>
        </visual>
        <inertial>
            <mass value="1e-5" />
            <origin rpy="0 0 0" xyz="0 0 0" />
            <inertia ixx="1e-6" ixy="0" ixz="0" iyy="1e-6" iyz="0" izz="1e-6" />
        </inertial>
    </link>
    <joint name="camera_optical_joint_right" type="fixed">
        <origin rpy="-1.5707963267948966 0 -1.5707963267948966" xyz="0 0 0" />
        <parent link="camera_right" />
        <child link="camera_optical_right" />
    </joint>
    <link name="camera_optical_right" />
    <gazebo reference="camera_right">
        <!-- <material>Gazebo/Black</material> -->
        <sensor name="camera_right_camera" type="depth">
            <update_rate>16</update_rate>
            <camera>
                <horizontal_fov>2.094</horizontal_fov>
                <image>
                    <width>928</width>
                    <height>800</height>
                    <format>R8G8B8</format>
                </image>
                <clip>
                    <near>0.1</near>
                    <far>5</far>
                </clip>
            </camera>
            <plugin filename="libgazebo_ros_openni_kinect.so" name="camera_right_controller">
                <baseline>0.025</baseline>
                <alwaysOn>true</alwaysOn>
                <updateRate>0.0</updateRate>
                <cameraName>camera_right_ir</cameraName>
                <imageTopicName>/camera_right/color/image_raw</imageTopicName>
                <cameraInfoTopicName>/camera_right/color/camera_info</cameraInfoTopicName>
                <depthImageTopicName>/camera_right/depth/image_raw</depthImageTopicName>
                <depthImageInfoTopicName>/camera_right/depth/camera_info</depthImageInfoTopicName>
                <!-- <pointCloudTopicName>/camera_${name}/depth/points</pointCloudTopicName> -->
                <pointCloudTopicName>/cam4/point_cloud_right</pointCloudTopicName>
                <frameName>camera_optical_right</frameName>
                <pointCloudCutoff>0.1</pointCloudCutoff>
                <pointCloudCutoffMax>1.5</pointCloudCutoffMax>
                <distortionK1>0.0</distortionK1>
                <distortionK2>0.0</distortionK2>
                <distortionK3>0.0</distortionK3>
                <distortionT1>0.0</distortionT1>
                <distortionT2>0.0</distortionT2>
                <CxPrime>0</CxPrime>
                <Cx>0.0045</Cx>
                <Cy>0.0039</Cy>
                <focalLength>0</focalLength>
                <hackBaseline>0</hackBaseline>
            </plugin>
        </sensor>
    </gazebo>
    <joint name="camera_joint_rearDown" type="fixed">
        <origin rpy="3.141592653589793 1.5707963267948966 0" xyz="-0.0825 0.0125 -0.04365" />
        <parent link="trunk" />
        <child link="camera_rearDown" />
    </joint>
    <link name="camera_rearDown">
        <collision>
            <origin rpy="0 0 0" xyz="0 0 0" />
            <geometry>
                <box size=".001 .001 .001" />
            </geometry>
        </collision>
        <visual>
            <origin rpy="0 0 0" xyz="0 0 0" />
            <geometry>
                <mesh filename="package://go1_description/meshes/depthCamera.dae" scale="1 1 1" />
            </geometry>
        </visual>
        <inertial>
            <mass value="1e-5" />
            <origin rpy="0 0 0" xyz="0 0 0" />
            <inertia ixx="1e-6" ixy="0" ixz="0" iyy="1e-6" iyz="0" izz="1e-6" />
        </inertial>
    </link>
    <joint name="camera_optical_joint_rearDown" type="fixed">
        <origin rpy="-1.5707963267948966 0 -1.5707963267948966" xyz="0 0 0" />
        <parent link="camera_rearDown" />
        <child link="camera_optical_rearDown" />
    </joint>
    <link name="camera_optical_rearDown" />
    <gazebo reference="camera_rearDown">
        <!-- <material>Gazebo/Black</material> -->
        <sensor name="camera_rearDown_camera" type="depth">
            <update_rate>16</update_rate>
            <camera>
                <horizontal_fov>2.094</horizontal_fov>
                <image>
                    <width>928</width>
                    <height>800</height>
                    <format>R8G8B8</format>
                </image>
                <clip>
                    <near>0.1</near>
                    <far>5</far>
                </clip>
            </camera>
            <plugin filename="libgazebo_ros_openni_kinect.so" name="camera_rearDown_controller">
                <baseline>0.025</baseline>
                <alwaysOn>true</alwaysOn>
                <updateRate>0.0</updateRate>
                <cameraName>camera_rearDown_ir</cameraName>
                <imageTopicName>/camera_rearDown/color/image_raw</imageTopicName>
                <cameraInfoTopicName>/camera_rearDown/color/camera_info</cameraInfoTopicName>
                <depthImageTopicName>/camera_rearDown/depth/image_raw</depthImageTopicName>
                <depthImageInfoTopicName>/camera_rearDown/depth/camera_info</depthImageInfoTopicName>
                <!-- <pointCloudTopicName>/camera_${name}/depth/points</pointCloudTopicName> -->
                <pointCloudTopicName>/cam5/point_cloud_rearDown</pointCloudTopicName>
                <frameName>camera_optical_rearDown</frameName>
                <pointCloudCutoff>0.1</pointCloudCutoff>
                <pointCloudCutoffMax>1.5</pointCloudCutoffMax>
                <distortionK1>0.0</distortionK1>
                <distortionK2>0.0</distortionK2>
                <distortionK3>0.0</distortionK3>
                <distortionT1>0.0</distortionT1>
                <distortionT2>0.0</distortionT2>
                <CxPrime>0</CxPrime>
                <Cx>0.0045</Cx>
                <Cy>0.0039</Cy>
                <focalLength>0</focalLength>
                <hackBaseline>0</hackBaseline>
            </plugin>
        </sensor>
    </gazebo>
    <joint name="camera_laserscan_joint_left" type="fixed">
        <origin rpy="0 0.2618 0" xyz="0 0 0" />
        <parent link="camera_left" />
        <child link="camera_laserscan_link_left" />
    </joint>
    <link name="camera_laserscan_link_left" />
    <joint name="camera_laserscan_joint_right" type="fixed">
        <origin rpy="0 0.2618 0" xyz="0 0 0" />
        <parent link="camera_right" />
        <child link="camera_laserscan_link_right" />
    </joint>
    <link name="camera_laserscan_link_right" />
    <joint name="ultraSound_joint_left" type="fixed">
        <origin rpy="0 0.2618 1.5707963267948966" xyz="-0.0535  0.0826 0.00868" />
        <parent link="trunk" />
        <child link="ultraSound_left" />
    </joint>
    <link name="ultraSound_left">
        <collision>
            <origin rpy="0 0 0" xyz="0 0 0" />
            <geometry>
                <box size=".001 .001 .001" />
            </geometry>
        </collision>
        <visual>
            <origin rpy="0 0 0" xyz="0 0 0" />
            <geometry>
                <mesh filename="package://go1_description/meshes/ultraSound.dae" scale="1 1 1" />
            </geometry>
            <material name="black" />
        </visual>
        <inertial>
            <mass value="1e-5" />
            <origin rpy="0 0 0" xyz="0 0 0" />
            <inertia ixx="1e-6" ixy="0" ixz="0" iyy="1e-6" iyz="0" izz="1e-6" />
        </inertial>
    </link>
    <joint name="ultraSound_joint_right" type="fixed">
        <origin rpy="0 0.2618 -1.5707963267948966" xyz="-0.0535 -0.0826 0.00868" />
        <parent link="trunk" />
        <child link="ultraSound_right" />
    </joint>
    <link name="ultraSound_right">
        <collision>
            <origin rpy="0 0 0" xyz="0 0 0" />
            <geometry>
                <box size=".001 .001 .001" />
            </geometry>
        </collision>
        <visual>
            <origin rpy="0 0 0" xyz="0 0 0" />
            <geometry>
                <mesh filename="package://go1_description/meshes/ultraSound.dae" scale="1 1 1" />
            </geometry>
            <material name="black" />
        </visual>
        <inertial>
            <mass value="1e-5" />
            <origin rpy="0 0 0" xyz="0 0 0" />
            <inertia ixx="1e-6" ixy="0" ixz="0" iyy="1e-6" iyz="0" izz="1e-6" />
        </inertial>
    </link>
    <joint name="ultraSound_joint_face" type="fixed">
        <origin rpy="0 0 0" xyz="0.2747 0.0 -0.0088" />
        <parent link="trunk" />
        <child link="ultraSound_face" />
    </joint>
    <link name="ultraSound_face">
        <collision>
            <origin rpy="0 0 0" xyz="0 0 0" />
            <geometry>
                <box size=".001 .001 .001" />
            </geometry>
        </collision>
        <visual>
            <origin rpy="0 0 0" xyz="0 0 0" />
            <geometry>
                <mesh filename="package://go1_description/meshes/ultraSound.dae" scale="1 1 1" />
            </geometry>
            <material name="black" />
        </visual>
        <inertial>
            <mass value="1e-5" />
            <origin rpy="0 0 0" xyz="0 0 0" />
            <inertia ixx="1e-6" ixy="0" ixz="0" iyy="1e-6" iyz="0" izz="1e-6" />
        </inertial>
    </link>
    <link name="base">
        <visual>
            <geometry>
                <mesh filename="package://mycobot_description/urdf/mycobot_320_pi_2022/ade/base.dae" />
            </geometry>
            <origin rpy=" 0 0 1.5708" xyz="0.0 0.0 0.0 " />
        </visual>
        <collision>
            <origin rpy=" 0 0 1.5708" xyz="0.0 0.0 0.0 " />
            <geometry>
                <cylinder length="0.102" radius="0.0725" />
            </geometry>
        </collision>
        <inertial>
            <mass value="0.01" />
            <origin rpy="0 0 0" xyz="0 0 0" />
            <inertia ixx="0.1" ixy="0.0" ixz="0.0" iyy="0.1" iyz="0.0" izz="0.1" />
        </inertial>
    </link>
    <link name="link1">
        <visual>
            <geometry>
                <mesh filename="package://mycobot_description/urdf/mycobot_320_pi_2022/ade/link1.dae" />
            </geometry>
            <origin rpy=" 0 0 1.5708" xyz="0.0 0.0 -0.078 " />
        </visual>
        <collision>
            <origin rpy=" 0 0 1.5708" xyz="0.0 0.0 -0.078 " />
            <geometry>
                <cylinder length="0.106" radius="0.043" />
            </geometry>
        </collision>
        <inertial>
            <mass value="0.01" />
            <origin rpy="0 0 0" xyz="0 0 0" />
            <inertia ixx="0.1" ixy="0.0" ixz="0.0" iyy="0.1" iyz="0.0" izz="0.1" />
        </inertial>
    </link>
    <link name="link2">
        <visual>
            <geometry>
                <mesh filename="package://mycobot_description/urdf/mycobot_320_pi_2022/ade/link2.dae" />
            </geometry>
            <origin rpy=" 0 1.5708 0" xyz="0.0 0.0 -0.04 " />
        </visual>
        <collision>
            <origin rpy=" 0 1.5708 0" xyz="0.0 0.0 -0.04 " />
            <geometry>
                <cylinder length="0.18" radius="0.036" />
            </geometry>
        </collision>
        <inertial>
            <mass value="0.01" />
            <origin rpy="0 0 0" xyz="0 0 0" />
            <inertia ixx="0.1" ixy="0.0" ixz="0.0" iyy="0.1" iyz="0.0" izz="0.1" />
        </inertial>
    </link>
    <link name="link3">
        <visual>
            <geometry>
                <mesh filename="package://mycobot_description/urdf/mycobot_320_pi_2022/ade/link3.dae" />
            </geometry>
            <origin rpy=" 1.5708 1.5708 1.5708" xyz="0.0 0.0 0.039 " />
        </visual>
        <collision>
            <origin rpy=" 1.5708 1.5708 1.5708" xyz="0.0 0.0 0.039 " />
            <geometry>
                <cylinder length="0.14" radius="0.0305" />
            </geometry>
        </collision>
        <inertial>
            <mass value="0.01" />
            <origin rpy="0 0 0" xyz="0 0 0" />
            <inertia ixx="0.1" ixy="0.0" ixz="0.0" iyy="0.1" iyz="0.0" izz="0.1" />
        </inertial>
    </link>
    <link name="link4">
        <visual>
            <geometry>
                <mesh filename="package://mycobot_description/urdf/mycobot_320_pi_2022/ade/link4.dae" />
            </geometry>
            <origin rpy=" 1.5708 1.5708 0" xyz="0.0 -0.0024 -0.05" />
        </visual>
        <collision>
            <origin rpy=" 1.5708 1.5708 0" xyz="0.0 -0.0024 -0.05" />
            <geometry>
                <cylinder length="0.083" radius="0.029" />
            </geometry>
        </collision>
        <inertial>
            <mass value="0.01" />
            <origin rpy="0 0 0" xyz="0 0 0" />
            <inertia ixx="0.1" ixy="0.0" ixz="0.0" iyy="0.1" iyz="0.0" izz="0.1" />
        </inertial>
    </link>
    <link name="link5">
        <visual>
            <geometry>
                <mesh filename="package://mycobot_description/urdf/mycobot_320_pi_2022/ade/link5.dae" />
            </geometry>
            <origin rpy=" 0  0 -1.5708" xyz="0.0 0.0 -0.05 " />
        </visual>
        <collision>
            <origin rpy=" 0  0 -1.5708" xyz="0.0 0.0 -0.05 " />
            <geometry>
                <cylinder length="0.0849" radius="0.029" />
            </geometry>
        </collision>
        <inertial>
            <mass value="0.01" />
            <origin rpy="0 0 0" xyz="0 0 0" />
            <inertia ixx="0.1" ixy="0.0" ixz="0.0" iyy="0.1" iyz="0.0" izz="0.1" />
        </inertial>
    </link>
    <link name="link6">
        <visual>
            <geometry>
                <mesh filename="package://mycobot_description/urdf/mycobot_320_pi_2022/ade/link6.dae" />
            </geometry>
            <material name="grey">
                <color rgba="0.5 0.5 0.5 1" />
            </material>
            <origin rpy=" 1.5708 1.5708 0" xyz="0.0 0.0 -0.022 " />
        </visual>
        <collision>
            <origin rpy=" 1.5708 1.5708 0" xyz="0.0 0.0 -0.022 " />
            <geometry>
                <cylinder length="0.0225" radius="0.026" />
            </geometry>
        </collision>
        <inertial>
            <mass value="0.01" />
            <origin rpy="0 0 0" xyz="0 0 0" />
            <inertia ixx="0.1" ixy="0.0" ixz="0.0" iyy="0.1" iyz="0.0" izz="0.1" />
        </inertial>
    </link>
    <!-- camera body, with origin at bottom screw mount -->
    <joint name="d435_joint" type="fixed">
        <origin rpy="0 -1.5708 1.5708 " xyz="0 -0.05 -0.015" />
        <parent link="link6" />
        <child link="d435_bottom_screw_frame" />
    </joint>
    <link name="d435_bottom_screw_frame" />
    <joint name="d435_link_joint" type="fixed">
        <origin rpy="0 0 0" xyz="0 0.0175 0.0125" />
        <parent link="d435_bottom_screw_frame" />
        <child link="d435_link" />
    </joint>
    <link name="d435_link">
        <visual>
            <origin rpy="1.5707963267948966 0 1.5707963267948966" xyz="0.0149 -0.0175 0" />
            <geometry>
                <mesh filename="package://mycobot_description/urdf/mycobot_320_pi_2022/camera/realsense_d435.stl" />
            </geometry>
        </visual>
        <collision>
            <origin rpy="0 0 0" xyz="0 -0.0175 0" />
            <geometry>
                <box size="0.02505 0.09 0.025" />
            </geometry>
        </collision>
        <inertial>
            <mass value="0.01" />
            <origin rpy="0 0 0" xyz="0 -0.0175 0" />
            <inertia ixx="0.01" ixy="0" ixz="0" iyy="0.01" iyz="0" izz="0.01" />
        </inertial>
    </link>
    <!-- camera depth joints and links -->
    <joint name="d435_depth_joint" type="fixed">
        <origin rpy="0 0 0" xyz="0 0 0" />
        <parent link="d435_link" />
        <child link="d435_depth_frame" />
    </joint>
    <link name="d435_depth_frame" />
    <joint name="d435_depth_optical_joint" type="fixed">
        <origin rpy="-1.5707963267948966 0 -1.5707963267948966" xyz="0 0 0" />
        <parent link="d435_depth_frame" />
        <child link="d435_depth_optical_frame" />
    </joint>
    <link name="d435_depth_optical_frame" />
    <!-- camera left IR joints and links -->
    <joint name="d435_left_ir_joint" type="fixed">
        <origin rpy="0 0 0" xyz="0 0.0 0" />
        <parent link="d435_depth_frame" />
        <child link="d435_left_ir_frame" />
    </joint>
    <link name="d435_left_ir_frame" />
    <joint name="d435_left_ir_optical_joint" type="fixed">
        <origin rpy="-1.5707963267948966 0 -1.5707963267948966" xyz="0 0 0" />
        <parent link="d435_left_ir_frame" />
        <child link="d435_left_ir_optical_frame" />
    </joint>
    <link name="d435_left_ir_optical_frame" />
    <!-- camera right IR joints and links -->
    <joint name="d435_right_ir_joint" type="fixed">
        <origin rpy="0 0 0" xyz="0 -0.05 0" />
        <parent link="d435_depth_frame" />
        <child link="d435_right_ir_frame" />
    </joint>
    <link name="d435_right_ir_frame" />
    <joint name="d435_right_ir_optical_joint" type="fixed">
        <origin rpy="-1.5707963267948966 0 -1.5707963267948966" xyz="0 0 0" />
        <parent link="d435_right_ir_frame" />
        <child link="d435_right_ir_optical_frame" />
    </joint>
    <link name="d435_right_ir_optical_frame" />
    <!-- camera color joints and links -->
    <joint name="d435_color_joint" type="fixed">
        <origin rpy="0 0 0" xyz="0 0.015 0" />
        <parent link="d435_depth_frame" />
        <child link="d435_color_frame" />
    </joint>
    <link name="d435_color_frame" />
    <joint name="d435_color_optical_joint" type="fixed">
        <origin rpy="-1.5707963267948966 0 -1.5707963267948966" xyz="0 0 0" />
        <parent link="d435_color_frame" />
        <child link="d435_color_optical_frame" />
    </joint>
    <link name="d435_color_optical_frame" />
    <!-- gazebo plugin -->
    <gazebo reference="d435_link">
        <self_collide>0</self_collide>
        <enable_wind>0</enable_wind>
        <kinematic>0</kinematic>
        <gravity>1</gravity>
        <mu2>1</mu2>
        <fdir1>0 0 0</fdir1>
        <kp>1e+13</kp>
        <kd>1</kd>
        <sensor name="d435_color" type="camera">
            <camera name="d435">
                <horizontal_fov>0.5235987755982988</horizontal_fov>
                <!--3069.4-->
                <image>
                    <width>640</width>
                    <height>480</height>
                    <format>RGB_INT8</format>
                </image>
                <clip>
                    <near>0.1</near>
                    <far>100</far>
                </clip>
                <noise>
                    <type>gaussian</type>
                    <mean>0.0</mean>
                    <stddev>0.007</stddev>
                </noise>
            </camera>
            <always_on>1</always_on>
            <update_rate>30</update_rate>
            <visualize>1</visualize>
        </sensor>
        <sensor name="d435_ired1" type="camera">
            <camera name="d435">
                <horizontal_fov>1.4870205226991688</horizontal_fov>
                <image>
                    <width>1280</width>
                    <height>720</height>
                    <format>L_INT8</format>
                </image>
                <clip>
                    <near>0.1</near>
                    <far>100</far>
                </clip>
                <noise>
                    <type>gaussian</type>
                    <mean>0.0</mean>
                    <stddev>0.05</stddev>
                </noise>
            </camera>
            <always_on>1</always_on>
            <update_rate>90</update_rate>
            <visualize>0</visualize>
        </sensor>
        <sensor name="d435_ired2" type="camera">
            <camera name="d435">
                <horizontal_fov>1.4870205226991688</horizontal_fov>
                <image>
                    <width>1280</width>
                    <height>720</height>
                    <format>L_INT8</format>
                </image>
                <clip>
                    <near>0.1</near>
                    <far>100</far>
                </clip>
                <noise>
                    <type>gaussian</type>
                    <mean>0.0</mean>
                    <stddev>0.05</stddev>
                </noise>
            </camera>
            <always_on>1</always_on>
            <update_rate>90</update_rate>
            <visualize>0</visualize>
        </sensor>
        <sensor name="d435_depth" type="depth">
            <camera name="d435">
                <horizontal_fov>1.4870205226991688</horizontal_fov>
                <image>
                    <width>1280</width>
                    <height>720</height>
                </image>
                <clip>
                    <near>0.1</near>
                    <far>100</far>
                </clip>
                <noise>
                    <type>gaussian</type>
                    <mean>0.0</mean>
                    <stddev>0.100</stddev>
                </noise>
            </camera>
            <always_on>1</always_on>
            <update_rate>90</update_rate>
            <visualize>0</visualize>
        </sensor>
        <sensor name="imu_sensor" type="imu">
            <always_on>true</always_on>
            <update_rate>200</update_rate>
            <visualize>true</visualize>
            <topic>__default_topic__</topic>
            <plugin filename="libgazebo_ros_imu_sensor.so" name="imu_plugin">
                <topicName>d435i/imu</topicName>
                <bodyName>camera_link</bodyName>
                <updateRateHZ>200.0</updateRateHZ>
                <gaussianNoise>0.0</gaussianNoise>
                <xyzOffset>0.0 0.0 0.0</xyzOffset>
                <rpyOffset>0.0 0.0 0.0</rpyOffset>
                <frameName>imu_link_</frameName>
            </plugin>
            <pose>0 0 0 0 0 0</pose>
        </sensor>
    </gazebo>
    <gazebo>
        <plugin filename="librealsense_gazebo_plugin.so" name="d435">
            <prefix>d435_</prefix>
            <depthUpdateRate>10</depthUpdateRate>
            <colorUpdateRate>10</colorUpdateRate>
            <infraredUpdateRate>10</infraredUpdateRate>
            <depthTopicName>depth/image_raw</depthTopicName>
            <depthCameraInfoTopicName>depth/camera_info</depthCameraInfoTopicName>
            <colorTopicName>color/image_raw</colorTopicName>
            <colorCameraInfoTopicName>color/camera_info</colorCameraInfoTopicName>
            <infrared1TopicName>infra1/image_raw</infrared1TopicName>
            <infrared1CameraInfoTopicName>infra1/camera_info</infrared1CameraInfoTopicName>
            <infrared2TopicName>infra2/image_raw</infrared2TopicName>
            <infrared2CameraInfoTopicName>infra2/camera_info</infrared2CameraInfoTopicName>
            <colorOpticalframeName>d435_color_optical_frame</colorOpticalframeName>
            <depthOpticalframeName>d435_depth_optical_frame</depthOpticalframeName>
            <infrared1OpticalframeName>d435_infrared1_optical_frame</infrared1OpticalframeName>
            <infrared2OpticalframeName>d435_infrared2_optical_frame</infrared2OpticalframeName>
            <rangeMinDepth>0.2</rangeMinDepth>
            <rangeMaxDepth>10.0</rangeMaxDepth>
            <pointCloud>false</pointCloud>
            <pointCloudTopicName>depth/color/points</pointCloudTopicName>
            <pointCloudCutoff>0.25</pointCloudCutoff>
            <pointCloudCutoffMax>9.0</pointCloudCutoffMax>
        </plugin>
    </gazebo>
    <joint name="joint2_to_joint1" type="revolute">
        <axis xyz="0 0 1" />
        <limit effort="5000.0" lower="-2.96" upper="2.96" velocity="2.0" />
        <parent link="base" />
        <child link="link1" />
        <origin rpy="0 0 0" xyz="0 0 0.173" />
    </joint>
    <joint name="joint3_to_joint2" type="revolute">
        <axis xyz="0 0 1" />
        <limit effort="5000.0" lower="-2.79" upper="2.79" velocity="2.0" />
        <parent link="link1" />
        <child link="link2" />
        <origin rpy="0 -1.57080  1.57080" xyz="0 -0.086  0" />
    </joint>
    <joint name="joint4_to_joint3" type="revolute">
        <axis xyz=" 0 0 1" />
        <limit effort="5000.0" lower="-2.79" upper="2.79" velocity="2.0" />
        <parent link="link2" />
        <child link="link3" />
        <origin rpy="0 0 0" xyz="0.13635 0 -0.086   " />
    </joint>
    <joint name="joint5_to_joint4" type="revolute">
        <axis xyz=" 0 0 1" />
        <limit effort="5000.0" lower="-2.79" upper="2.79" velocity="2.0" />
        <parent link="link3" />
        <child link="link4" />
        <origin rpy="0 0 1.57080" xyz="0.1195 0  0.082" />
    </joint>
    <joint name="joint6_to_joint5" type="revolute">
        <axis xyz="0 0 1" />
        <limit effort="5000.0" lower="-2.96" upper="2.96" velocity="2.0" />
        <parent link="link4" />
        <child link="link5" />
        <origin rpy="1.57080 0 0" xyz="0 -0.09415 0" />
    </joint>
    <joint name="joint6output_to_joint6" type="revolute">
        <axis xyz="0 0 1" />
        <limit effort="5000.0" lower="-3.05" upper="3.05" velocity="2.0" />
        <parent link="link5" />
        <child link="link6" />
        <origin rpy="-1.57080 0 0 " xyz="0 0.055 0" />
    </joint>
    <transmission name="trans_joint2_to_joint1">
        <type>transmission_interface/SimpleTransmission</type>
        <joint name="joint2_to_joint1">
            <hardwareInterface>hardware_interface/EffortJointInterface</hardwareInterface>
        </joint>
        <actuator name="joint2_to_joint1_motor">
            <hardwareInterface>hardware_interface/EffortJointInterface</hardwareInterface>
            <mechanicalReduction>1</mechanicalReduction>
        </actuator>
    </transmission>
    <transmission name="trans_joint3_to_joint2">
        <type>transmission_interface/SimpleTransmission</type>
        <joint name="joint3_to_joint2">
            <hardwareInterface>hardware_interface/EffortJointInterface</hardwareInterface>
        </joint>
        <actuator name="joint3_to_joint2_motor">
            <hardwareInterface>hardware_interface/EffortJointInterface</hardwareInterface>
            <mechanicalReduction>1</mechanicalReduction>
        </actuator>
    </transmission>
    <transmission name="trans_joint4_to_joint3">
        <type>transmission_interface/SimpleTransmission</type>
        <joint name="joint4_to_joint3">
            <hardwareInterface>hardware_interface/EffortJointInterface</hardwareInterface>
        </joint>
        <actuator name="joint4_to_joint3_motor">
            <hardwareInterface>hardware_interface/EffortJointInterface</hardwareInterface>
            <mechanicalReduction>1</mechanicalReduction>
        </actuator>
    </transmission>
    <transmission name="trans_joint5_to_joint4">
        <type>transmission_interface/SimpleTransmission</type>
        <joint name="joint5_to_joint4">
            <hardwareInterface>hardware_interface/EffortJointInterface</hardwareInterface>
        </joint>
        <actuator name="joint5_to_joint4_motor">
            <hardwareInterface>hardware_interface/EffortJointInterface</hardwareInterface>
            <mechanicalReduction>1</mechanicalReduction>
        </actuator>
    </transmission>
    <transmission name="trans_joint6_to_joint5">
        <type>transmission_interface/SimpleTransmission</type>
        <joint name="joint6_to_joint5">
            <hardwareInterface>hardware_interface/EffortJointInterface</hardwareInterface>
        </joint>
        <actuator name="joint6_to_joint5_motor">
            <hardwareInterface>hardware_interface/EffortJointInterface</hardwareInterface>
            <mechanicalReduction>1</mechanicalReduction>
        </actuator>
    </transmission>
    <transmission name="trans_joint6output_to_joint6">
        <type>transmission_interface/SimpleTransmission</type>
        <joint name="joint6output_to_joint6">
            <hardwareInterface>hardware_interface/EffortJointInterface</hardwareInterface>
        </joint>
        <actuator name="joint6output_to_joint6_motor">
            <hardwareInterface>hardware_interface/EffortJointInterface</hardwareInterface>
            <mechanicalReduction>1</mechanicalReduction>
        </actuator>
    </transmission>
    <gazebo>
        <plugin filename="libgazebo_ros_control.so" name="gazebo_ros_control">
            <robotNamespace>/</robotNamespace>
        </plugin>
    </gazebo>
</robot>

